[2024-02-18 16:20:18 +0000] [1] [INFO] Starting gunicorn 21.2.0
[2024-02-18 16:20:18 +0000] [1] [INFO] Listening at: http://0.0.0.0:8000 (1)
[2024-02-18 16:20:18 +0000] [1] [INFO] Using worker: sync
[2024-02-18 16:20:18 +0000] [17] [INFO] Booting worker with pid: 17
[2024-02-18 16:20:18 +0000] [18] [INFO] Booting worker with pid: 18
[2024-02-18 16:20:18 +0000] [19] [INFO] Booting worker with pid: 19
[2024-02-18 16:20:18 +0000] [20] [INFO] Booting worker with pid: 20
[2024-02-18 10:20:33 -0600] [19] [ERROR] Error handling request /
Traceback (most recent call last):
  File "/usr/local/lib/python3.12/site-packages/gunicorn/workers/sync.py", line 135, in handle
    self.handle_request(listener, req, client, addr)
  File "/usr/local/lib/python3.12/site-packages/gunicorn/workers/sync.py", line 178, in handle_request
    respiter = self.wsgi(environ, resp.start_response)
               ^^^^^^^^^^^^^^^^^^^^^^^^^^^^^^^^^^^^^^^
  File "/usr/local/lib/python3.12/site-packages/django/core/handlers/wsgi.py", line 124, in __call__
    response = self.get_response(request)
               ^^^^^^^^^^^^^^^^^^^^^^^^^^
  File "/usr/local/lib/python3.12/site-packages/django/core/handlers/base.py", line 139, in get_response
    set_urlconf(settings.ROOT_URLCONF)
                ^^^^^^^^^^^^^^^^^^^^^
  File "/usr/local/lib/python3.12/site-packages/django/conf/__init__.py", line 104, in __getattr__
    val = getattr(_wrapped, name)
          ^^^^^^^^^^^^^^^^^^^^^^^
AttributeError: 'Settings' object has no attribute 'ROOT_URLCONF'
[2024-02-18 10:20:38 -0600] [20] [ERROR] Error handling request /
Traceback (most recent call last):
  File "/usr/local/lib/python3.12/site-packages/gunicorn/workers/sync.py", line 135, in handle
    self.handle_request(listener, req, client, addr)
  File "/usr/local/lib/python3.12/site-packages/gunicorn/workers/sync.py", line 178, in handle_request
    respiter = self.wsgi(environ, resp.start_response)
               ^^^^^^^^^^^^^^^^^^^^^^^^^^^^^^^^^^^^^^^
  File "/usr/local/lib/python3.12/site-packages/django/core/handlers/wsgi.py", line 124, in __call__
    response = self.get_response(request)
               ^^^^^^^^^^^^^^^^^^^^^^^^^^
  File "/usr/local/lib/python3.12/site-packages/django/core/handlers/base.py", line 139, in get_response
    set_urlconf(settings.ROOT_URLCONF)
                ^^^^^^^^^^^^^^^^^^^^^
  File "/usr/local/lib/python3.12/site-packages/django/conf/__init__.py", line 104, in __getattr__
    val = getattr(_wrapped, name)
          ^^^^^^^^^^^^^^^^^^^^^^^
AttributeError: 'Settings' object has no attribute 'ROOT_URLCONF'
[2024-02-18 16:22:01 +0000] [1] [CRITICAL] WORKER TIMEOUT (pid:18)
[2024-02-18 10:22:01 -0600] [18] [INFO] Worker exiting (pid: 18)
[2024-02-18 16:22:02 +0000] [1] [ERROR] Worker (pid:18) exited with code 1
[2024-02-18 16:22:02 +0000] [1] [ERROR] Worker (pid:18) exited with code 1.
[2024-02-18 16:22:02 +0000] [21] [INFO] Booting worker with pid: 21
[2024-02-18 16:28:42 +0000] [1] [INFO] Handling signal: term
[2024-02-18 10:28:42 -0600] [19] [INFO] Worker exiting (pid: 19)
[2024-02-18 10:28:42 -0600] [20] [INFO] Worker exiting (pid: 20)
[2024-02-18 10:28:42 -0600] [17] [INFO] Worker exiting (pid: 17)
[2024-02-18 10:28:42 -0600] [21] [INFO] Worker exiting (pid: 21)
[2024-02-18 16:28:42 +0000] [1] [INFO] Shutting down: Master
